Workbook
Name cfRep: INDEX(#REF!,1,Bois!Mun_col_num) : INDEX(#REF!,COUNTA(Mun_col),Bois!Mun_col_num)
Name cfRep: INDEX(#REF!,1,Mun_col_num) : INDEX(#REF!,COUNTA(Mun_col),Mun_col_num)
Name choix_affichage: #REF!
Name Mun_col_num: MATCH(Ville,Municipalite,0)
Name Mun_col_num: MATCH(Ville,Municipalite,0)
Name Municipalite: #REF!
Name Ville: #REF!

Sheet Bois
A1: No d'enr. | B1: SIA | C1: Date de l'acte ou de l'avant contrat | D1: Vendeur | E1: Acheteur | F1: Lots | G1: Prix de vente ($) | H1: Prix de vente redressé au temps ($) | I1: MRC | J1: Ville/Municipalité | K1: Adresse complète | L1: Latitude | M1: Longitude | N1: Superficie totale (ha) | O1: Zone agricole (CPTAQ) | P1: Topographie | Q1: Superficie boisée (ha) | R1: Superficie cultivée (ha) | S1: Feuillus/Résineux | T1: Proportion feuillus | U1: Proporition résineux | V1: Densité plantation | W1: Zones humides (ha) | X1: Zones humides types) | Y1: Bâtiments agricoles | Z1: Valeur contributive bâtiments agricoles ($) | AA1: Source valeur constributive bâtiments agricoles | AB1: Équipements | AC1: Superficie acéricole (ha) | AD1: Nombre d'entailles | AE1: Contingent acéricole (Livres) | AF1: Observations | AG1: Décisions CPTAQ | AH1: Taux unitaire global ($/ha) | AI1: $/entaille
A2: 22262068 | C2: 42487 | D2: Madeleine Therrien, | E2: Alain Paquet, Marlène Plamondon, | F2: 1826955 | G2: 52000 | I2: Jacques-Cartier | J2: Stoneham-et-Tewkesbury | K2: chemin plante, Stoneham-et-Tewkesbury | L2: 47.008199 | M2: -71.439817 | N2: 14.28 | O2: non | P2: déclivité | Q2: 14.28 | R2: 0 | S2: Resineux | T2: 0.4 | U2: 0.6 | AC2: 2 | AF2: enclavé, resineux | AH2: =Table2[[#This Row],[Prix de vente ($)]]/Table2[[#This Row],[Superficie totale (ha)]] -> 3641.4566
A3: 22486718 | C3: 42569 | D3: 9319-9644 QUÉBEC INC., | E3: Jean GAGNÉ, Jean-Simon GAGNÉ, | F3: 5748850 | G3: 74733.75 | I3: Jacques-Cartier | J3: Lac-Beauport | K3: Chemin de l'Orignal, Lac-Beauport | L3: 46.974046 | M3: -71.265846 | N3: 4 | O3: non | P3: legere declivite | Q3: 4 | R3: 0 | S3: Feuillus | T3: 0.6 | U3: 0.4 | AC3: 0 | AF3: accesible | AH3: =Table2[[#This Row],[Prix de vente ($)]]/Table2[[#This Row],[Superficie totale (ha)]] -> 18683.438
A4: 22 661 085 | C4: 42649 | F4: 5 085 264, 4 913 356 | G4: 133000 | I4: Les Appalaches | J4: Kinnear's Mills | K4: 5e rang, Kinnear's Mills | AH4: =Table2[[#This Row],[Prix de vente ($)]]/Table2[[#This Row],[Superficie totale (ha)]] -> #DIV/0!
A5: 22674380 | C5: 42657 | D5: 9319-9644 QUÉBEC INC., | E5: Louis-Robert COUTURE, | F5: 5748805 | G5: 80482 | I5: Jacques-Cartier | J5: Lac-Beauport | K5: chemin du chevreuil, Lac-Beauport | L5: 46.977771 | M5: -71.249590 | N5: 4.69 | O5: non | P5: legere declivite | Q5: 4.69 | R5: 0 | S5: Feuillus | T5: 0.6 | U5: 0.4 | AC5: 0 | AF5: accesible | AH5: =Table2[[#This Row],[Prix de vente ($)]]/Table2[[#This Row],[Superficie totale (ha)]] -> 17160.341
A6: 22845364 | C6: 42748 | D6: Gilles DUMONT, | E6: 9350-2185 QUÉBEC INC., | F6: 1496205 | G6: 40000 | I6: Jacques-Cartier | J6: Lac-Beauport | K6: Chemin de la Tournée, Lac-Beauport | L6: 46.994168 | M6: -71.330368 | N6: 19.58 | O6: non | P6: déclivité | Q6: 19.58 | R6: 0 | S6: Feuillus | T6: 0.7 | U6: 0.3 | AC6: 8 | AF6: enclavé | AH6: =Table2[[#This Row],[Prix de vente ($)]]/Table2[[#This Row],[Superficie totale (ha)]] -> 2042.9009
A7: 22999530 | C7: 42836 | D7: Sylvain BOUCHARD, | E7: Sarah BEAUDRY-MONTMINY, Jonathan CHEVANEL, | F7: 4015270 | G7: 25000 | I7: Jacques-Cartier | J7: Lac-Beauport | K7: Chemin de l'Eperon, Lac-Beauport | L7: 46.970935 | M7: -71.343376 | N7: 4.04 | O7: non | P7: Légère déclivité | Q7: 4.04 | R7: 0 | S7: Feuillus | T7: 0.85 | U7: 0.15 | AC7: 2.3 | AF7: enclavé | AH7: =Table2[[#This Row],[Prix de vente ($)]]/Table2[[#This Row],[Superficie totale (ha)]] -> 6188.1188
A8: 23017142 | C8: 42846 | D8: Darlène ANDELY, | E8: 9350-2185 QUÉBEC INC | F8: 4 950 989 | G8: 75000 | I8: Jacques-Cartier | J8: Stoneham-et-Tewkesbury | K8: Chemin de la Grand-ligne, Stoneham-et-Tewkesbury | L8: 46.976398 | M8: -71.397325 | N8: 14.41 | O8: non | P8: Légère déclivité | Q8: 14.28 | R8: 0 | S8: Feuillus | T8: 0.85 | U8: 0.15 | AC8: 14 | AF8: accesible | AH8: =Table2[[#This Row],[Prix de vente ($)]]/Table2[[#This Row],[Superficie totale (ha)]] -> 5204.7189
A9: 23035629 | C9: 42853 | D9: 9319-9644 QUÉBEC INC | E9: Jean-Jacques LACHANCE | F9: 5748847 | G9: 71859.38 | I9: Jacques-Cartier | J9: Lac-Beauport | K9: Chemin de l'Orignal, Lac-Beauport | L9: 46.972937 | M9: -71.265053 | N9: 4.15 | O9: non | P9: Légère déclivité | Q9: 4.15 | R9: 0 | S9: Feuillus | T9: 0.9 | U9: 0.1 | AC9: 4 | AF9: accesible | AH9: =Table2[[#This Row],[Prix de vente ($)]]/Table2[[#This Row],[Superficie totale (ha)]] -> 17315.513
A10: 23216736 | C10: 42921 | D10: Thomas Lepagne, | E10: Guy Roberge, | F10: 6111085 | G10: 20000 | I10: Jacques-Cartier | J10: Stoneham-et-Tewkesbury | K10: Chemin Whalen, Stoneham-et-Tewkesbury | L10: 47.031558 | M10: -71.300384 | N10: 17.42 | O10: non | P10: Légère déclivité | Q10: 17.42 | R10: 0 | S10: Feuillus | T10: 0.7 | U10: 0.3 | AC10: 1.4 | AF10: enclavé | AH10: =Table2[[#This Row],[Prix de vente ($)]]/Table2[[#This Row],[Superficie totale (ha)]] -> 1148.1056
B11: 24079958 | C11: 43255 | F11: 106-P, Paroisse St-François et suivants | G11: 219000 | I11: L'Ile-d'Orléans | J11: Saint-François-de-l'Île-d'Orléans | K11: Chemin Royal Saint-François-de-l'Île-d'Orléans | L11: 47.01169928504172 | M11: -70.8353380495719 | N11: 31.28 | O11: oui | P11: Légère pente | Q11: =0.9*N11 -> 28.152 | R11: =0.1*N11 -> 3.128 | S11: F | T11: 1 | U11: 0 | AC11: 6.7 | AF11: Peuplement peu dense. Nouveau lot 6 282 149 (?) | AH11: =Table2[[#This Row],[Prix de vente ($)]]/Table2[[#This Row],[Superficie totale (ha)]] -> 7001.2788 | AI11: =G11/AD11 -> #DIV/0!
A12: 28472646 | C12: 43604 | D12: MARCEL ST-PIERRE | E12: LES BLEUETS DU FJORD INC | F12: 4 307 834, 4 307 833, 4 307 831, 4 307 829 | G12: 2300000 | I12: L'Érable | J12: Princeville | K12: 3e Rang, Princeville | L12: 46.255515 | M12: -71.891197 | N12: 264.29 | O12: oui | P12: legère déclivité | Q12: 264.29 | R12: 0 | S12: Resineux | T12: 0.4 | U12: 0.6 | AC12: 57.1 | AF12: tres grande superficie, enclavé et presence de marècage et de tourbière | AH12: =Table2[[#This Row],[Prix de vente ($)]]/Table2[[#This Row],[Superficie totale (ha)]] -> 8702.5616
A13: 24977808 | C13: 43730 | D13: Frédéric BOUDREAULT | E13: Serge GAUTHIER | F13: 5 148 744 | G13: 20000 | I13: Manicouagan | J13: Ragueneau | K13: 2ieme rang,Ragueneau | L13: 49.094129 | M13: -68.510631 | N13: 42.48 | O13: non | P13: déclivité importante | Q13: 42,48 | R13: 0 | S13: mixte | T13: 0.5 | U13: 0.5 | AC13: 0 | AF13: zone humide (tourbière boisé) | AH13: =Table2[[#This Row],[Prix de vente ($)]]/Table2[[#This Row],[Superficie totale (ha)]] -> 470.80979
A14: 21646365 | C14: 43795 | F14: 37-1, 38-1,38-2,39-P,42-1-P | G14: 265000 | I14: L'Ile-d'Orléans | J14: Saint-François-de-l'Île-d'Orléans | K14: Chemin Royal Saint-François-de-l'Île-d'Orléans | L14: 47.00677149448989 | M14: ,-70.88060766039577 | N14: 29.91 | Y14: Cabane à sucre | AD14: 500 | AF14: Cabane à sucre équipée | AH14: =Table2[[#This Row],[Prix de vente ($)]]/Table2[[#This Row],[Superficie totale (ha)]] -> 8859.9131 | AI14: =G14/AD14 -> 530
A15: 28155797 | C15: 43820 | D15: JEAN-GUY McCUTCHEON | E15: GESTION KATE INC | F15: 5 135 333, 5 136 091 | G15: 45000 | I15: Les Appalaches | J15: Adstock | K15: 11 e rang, Adsyock | L15: 46.092829 | M15: -71.152622 | N15: =8.52+1.16 -> 9.68 | O15: oui | P15: déclivité | Q15: 9.68 | R15: 0 | S15: Feuillus | T15: 0.7 | U15: 0.3 | AC15: =0.9+5.1 -> 6 | AF15: servitude de passage | AH15: =Table2[[#This Row],[Prix de vente ($)]]/Table2[[#This Row],[Superficie totale (ha)]] -> 4648.7603
A16: 27663835 | C16: 43870 | D16: René LEMOYNE, Serge LEMOINE, Jean-Guy LEMOINE | E16: Martin RHÉAUME | F16: 3 698 485, 3 698 524 | G16: 180000 | I16: Les Maskoutains | J16: La Présentation | K16: Rue des Bas-Étangs, La présentation | L16: 45.690941 | M16: -73.026890 | N16: =5+4.19 -> 9.19 | O16: oui | P16: plane | Q16: 9.19 | R16: 0 | S16: Feuillus | T16: 0.65 | U16: 0.35 | AC16: =0.4+3.4 -> 3.8 | AF16: enclavé, presence d'un bâtiment | AH16: =Table2[[#This Row],[Prix de vente ($)]]/Table2[[#This Row],[Superficie totale (ha)]] -> 19586.507
A17: 25257302 | C17: 43900 | D17: Luc DESLAURIERS, Rémy GINGRAS | E17: MARC LABARRE MD INC | F17: 3 055 985, 3 055 990 | G17: 180000 | I17: Québec | J17: Saint-Augustin-de-Desmaures | K17: rang du Petit-Capsa, Saint-Augustin-de- Desmaures | L17: 46.771386 | M17: -71.595172 | N17: =21.55+14.69 -> 36.24 | O17: oui | P17: Plane | Q17: =Bois!$N2 -> 14.28 | S17: Mixte | T17: 0.5 | U17: 0.5 | AF17: Superficie coupe de 11,6 ha. 2 cours d'eau permanents. | AH17: =Table2[[#This Row],[Prix de vente ($)]]/Table2[[#This Row],[Superficie totale (ha)]] -> 4966.8874 | AI17: =Bois!#REF!/Bois!$AD2 -> #REF!
A18: 25698764 | C18: 44092 | D18: JALROU INC (Jacques et Pierre Roussin) | E18: Olivier BONNEAU, INITIAL5 INC (Pierre-Luc GIRARD) | F18: 3056045 | G18: 46500 | I18: Québec | J18: Saint-Augustin-de-Desmaures | K18: rang du Petit-Capsa, Saint-Augustin-de- Desmaures | L18: 46.775839 | M18: -71.528771 | N18: 9.94 | O18: oui | P18: Plane | Q18: =Bois!$N3 -> 4 | S18: Mixte (dominance résineux) | T18: 0.76 | U18: 0.24 | AF18: Servitude de passage. | AG18: 043813, 234861 (refus construction) et 023486 (refus) | AH18: =Table2[[#This Row],[Prix de vente ($)]]/Table2[[#This Row],[Superficie totale (ha)]] -> 4678.0684 | AI18: =Bois!$G3/Bois!$AD3 -> #DIV/0!
A19: 25771426 | C19: 44123 | D19: 9013-0998 QUÉBEC INC Denis LÉVEILLÉ | E19: VILLE DE CHAMBLY | F19: 2343104 | G19: 400000 | I19: La-Vallée-du-Richelieu | J19: Chambly | L19: 45.415208 | M19: -73.291752 | N19: 17.79 | O19: oui | P19: Plane | S19: Feuillus | T19: 1 | U19: 0 | V19: 80-90 % | AC19: 10.8 | AF19: Bordure Autoroute 10 | AG19: 444141 (corridor récréatif) | AH19: =Table2[[#This Row],[Prix de vente ($)]]/Table2[[#This Row],[Superficie totale (ha)]] -> 22484.542
B20: 26189122 | C20: 44145 | F20: 5347394 | G20: 100000 | I20: L'Islet | J20: Saint-Adalbert | K20: 281 Route 204 O. Saint-Adalbert | L20: 46.832026 | M20: -69.958992 | N20: 41.51 | O20: oui | P20: Déclivité | Q20: =N20 -> 41.51 | AC20: 18 | AD20: 800 | AF20: Potentiel 1000 entailles, comprend station de pompage, réservoir 1000 gallons, entrée électrique 200A, relâcheur CDL et tubulure 3 ans d'usage | AH20: =Table2[[#This Row],[Prix de vente ($)]]/Table2[[#This Row],[Superficie totale (ha)]] -> 2409.0581 | AI20: =G20/AD20 -> 125
A21: 25960460 | C21: 44146 | D21: Élizabeth SAVARD | E21: Denis ARSENAULT | F21: 3815365 | G21: 25000 | I21: La côte-de-Beaupré | J21: Saint-Joachim | K21: Route 138, Saint-Joachim | L21: 47.087231 | M21: -70.856026 | N21: 14.49 | O21: non | P21: legère déclivité | Q21: 14.49 | R21: 0 | S21: Feuillus | T21: 0.8 | U21: 0.2 | AC21: 0 | AF21: enclavé, pas de potentiel acéricole | AH21: =Table2[[#This Row],[Prix de vente ($)]]/Table2[[#This Row],[Superficie totale (ha)]] -> 1725.3278
A22: 25902207 | C22: 44168 | D22: 9266-1024 QUÉBEC INC Paul Miklis | E22: François Doucet, Nancy Coulombe | F22: 2 599 858, 2 599 863 | G22: 160000 | I22: La-Vallée-du-Richelieu | J22: Carignan | K22: Chemin Bellerive, Carignan | L22: 45.489065 | M22: -73.319346 | N22: 7.72 | O22: oui | P22: Plane | S22: Feuillus | T22: 0.9 | U22: 0.1 | V22: 80-89% | AC22: 2.1 | AH22: =Table2[[#This Row],[Prix de vente ($)]]/Table2[[#This Row],[Superficie totale (ha)]] -> 20725.389
A23: 26106753 | C23: 44168 | D23: Richard RACINE | E23: Alexandre JULIEN | F23: 3815209 | G23: 25000 | I23: La côte-de-Beaupré | J23: Saint-Joachim | K23: Rue de la Miche, Saint-Joachim | L23: 47.093106 | M23: -70.846615 | N23: 8.44 | O23: non | P23: legère déclivité | Q23: 7.24 | R23: 0 | S23: Feuillus | T23: 0.9 | U23: 0.1 | AC23: 2.3 | AF23: enclavé | AH23: =Table2[[#This Row],[Prix de vente ($)]]/Table2[[#This Row],[Superficie totale (ha)]] -> 2962.0853
A24: 25951684 | C24: 44183 | D24: Michel Bernard Henri KUN, Léopold Christian KUN | E24: 9418-1286 QUÉBEC INC Minying WU | F24: 2 601 589, 2 600 785 | G24: 340000 | I24: La-Vallée-du-Richelieu | J24: Carignan | K24: Chemin Bellerive, Carignan | L24: 45.417657 | M24: -73.371157 | N24: 25.96 | O24: oui | P24: Plane | R24: 3.9 | S24: Feuillus | T24: 1 | U24: 0 | V24: 60-69 % | AC24: 12 | AH24: =Table2[[#This Row],[Prix de vente ($)]]/Table2[[#This Row],[Superficie totale (ha)]] -> 13097.072
A25: 26114479 | C25: 44184 | D25: FERME BERNARD GAUTHIER INC | E25: CHARLES RHÉAUME | F25: 5719391, 5719402 | G25: 72500 | I25: Charlevoix | J25: Saint-Hilarion | K25: 1er rang Saint-Hilarion | L25: 47.583581 | M25: -70.304526 | N25: =(515709.594+713.4)/10000 -> 51.642299 | O25: oui | P25: déclivité | Q25: =Bois!$N4-Bois!#REF! -> #REF! | S25: Résineux | AF25: Terrain traversé par ligne hydro-Québec | AH25: =Table2[[#This Row],[Prix de vente ($)]]/Table2[[#This Row],[Superficie totale (ha)]] -> 1403.8879 | AI25: =Bois!$G4/Bois!$AD4 -> #DIV/0!
A26: 25960915 | C26: 44187 | D26: Michel CÔTÉ | E26: LORD'STACE INC | F26: 4 582 896, 4 582 898, 4 582 895, 4 582 897 | G26: 275000 | I26: La côte-de-Beaupré | J26: Chateau-Richer | K26: Chemin de la Mine , Chateau-Richer | L26: 46.978132 | M26: -71.082581 | N26: 79.36 | O26: oui | P26: legère déclivité | Q26: =79.36-2.7 -> 76.66 | R26: 0 | S26: Resineux | T26: 0.3 | U26: 0.7 | AC26: 4.3 | AF26: enclavé, servitude de passage | AH26: =Table2[[#This Row],[Prix de vente ($)]]/Table2[[#This Row],[Superficie totale (ha)]] -> 3465.2218
A27: 26145375 | C27: 44212 | D27: Raymond POMERLEAU | E27: Alexandre GUERTIN, Catherine LEBLOND | F27: 5286409 | G27: 200000 | I27: Val-Saint-François | J27: Stoke | K27: 11e rang Est Stoke | L27: 45.566664 | M27: -71.742207 | N27: 41.42 | O27: oui | P27: Plane | Q27: =Bois!$N5-6.5 -> -1.81 | S27: Mixte | T27: 0.55 | U27: 0.45 | V27: 0.8 | AF27: Environ 6 hectares terres et friches | AH27: =Table2[[#This Row],[Prix de vente ($)]]/Table2[[#This Row],[Superficie totale (ha)]] -> 4828.5852 | AI27: =Bois!$G5/Bois!$AD5 -> #DIV/0!
A28: 25995437 | C28: 44214 | D28: Serge Lessard | E28: Charles Bérubé, Catherine Arnautovitch | F28: 6212197 | G28: 190000 | I28: La côte-de-Beaupré | J28: Saint-Tite-des-Caps | K28: Avenue de la Montagne, Saint-Tite-des-Caps | L28: 47.087242 | M28: -70.803061 | N28: 17.69 | O28: non | P28: legère déclivité | Q28: 17.69 | R28: 0 | S28: Feuillus | T28: 1 | U28: 0 | AC28: 17.69 | AF28: enclavé, servitude de passage, tres grand potentiel acéricole | AH28: =Table2[[#This Row],[Prix de vente ($)]]/Table2[[#This Row],[Superficie totale (ha)]] -> 10740.531
A29: 26021098 | C29: 44223 | D29: INVESTISSEMENT SNDA INC | E29: Charles PERRON-GAUVREAU | F29: 4 582 936, 4 832 455 | G29: 375000 | I29: La côte-de-Beaupré | J29: Chateau-Richer | K29: Chemin de la Mine , Chateau-Richer | L29: 46.972116 | M29: -71.054997 | N29: 63.35 | O29: oui | P29: déclivité | Q29: 63.35 | R29: 0 | S29: Feuillus | T29: 0.7 | U29: 0.3 | AC29: 29 | AF29: enclavé, servitude de passage | AH29: =Table2[[#This Row],[Prix de vente ($)]]/Table2[[#This Row],[Superficie totale (ha)]] -> 5919.4949
A30: 26032402 | C30: 44228 | D30: Alain BOUTIN | E30: Réjean FONTAINE, Lucie MARQUIS | F30: 3 375 232 | G30: 17000 | I30: Bellechasse | J30: Saint-Anselme | K30: Chemin des Morins, Saint-Anselme | L30: 46.589837 | M30: -70.973579 | N30: 5.48 | O30: oui | P30: plane | Q30: 5.48 | R30: 0 | S30: Feuillus | T30: 0.65 | U30: 0.35 | AC30: 2.3 | AF30: enclavé | AH30: =Table2[[#This Row],[Prix de vente ($)]]/Table2[[#This Row],[Superficie totale (ha)]] -> 3102.1898
A31: 26073067 | C31: 44231 | D31: Lucien LECLERC | E31: Jean-Philippe MORIN | F31: 4479817 | G31: 12000 | I31: L'Islet | J31: Sainte-Louise | K31: Sainte-Louise | L31: 47.296726 | M31: -70.034757 | N31: 5.89 | O31: oui | P31: plane | Q31: =N31 -> 5.89 | AC31: 3.2 | AH31: =Table2[[#This Row],[Prix de vente ($)]]/Table2[[#This Row],[Superficie totale (ha)]] -> 2037.3514 | AI31: =G31/AD31 -> #DIV/0!
A32: 26130138 | C32: 44237 | D32: Yves TREMBLAY | E32: Maryse MORNEAU | F32: 4 917 664 | G32: 37000 | I32: Manicouagan | J32: Pointe-Lebel | K32: Rue Granier, PointeLebel | L32: 49.101 | M32: -68.206541 | N32: 3.25 | O32: non | P32: legere declivite | Q32: 3.25 | R32: 0 | S32: résineux | T32: 0.1 | U32: 0.9 | AC32: 0 | AF32: Zone humide (eau peu profonde) | AH32: =Table2[[#This Row],[Prix de vente ($)]]/Table2[[#This Row],[Superficie totale (ha)]] -> 11384.615
A33: 26303798 | C33: 44237 | D33: LA FERME PELLERAT (1997) INC (Gervais PELLETIER) | E33: Maxine PAQUET LESSARD, Christian MERCIER | F33: 4479790 | G33: 115000 | I33: L'Islet | J33: Sainte-Louise | K33: rang Bonnet Sainte-Louise | L33: 47.288848 | M33: -70.054129 | N33: 16.93 | O33: oui | P33: Forte déclivité | Q33: =N33 -> 16.93 | AC33: =2.4+7.3 -> 9.7 | AH33: =Table2[[#This Row],[Prix de vente ($)]]/Table2[[#This Row],[Superficie totale (ha)]] -> 6792.6757 | AI33: =G33/AD33 -> #DIV/0!
A34: 26147486 | C34: 44250 | D34: Dominic CLOUTIER, Alexandre CLOUTIER | E34: Daniel MUNOZ, Jean-François GAUTHIER, Jessica LANGLAIS, Tonio BARTOLO | F34: 3 387 451, 3 387 445, 3 632 106, 3 387 446 | G34: 158000 | I34: Lotbinière | J34: Saint-Apollinaire | K34: rang Saint-Lazare Saint-Apollinaire | L34: 46.615412 | M34: -71.403848 | N34: =18.86+2.3+0.33+0.74 -> 22.23 | O34: oui | P34: Plane | Q34: =Bois!$N6 -> 19.58 | S34: Feuillus | T34: 0.6 | U34: 0.4 | V34: 0.65 | AH34: =Table2[[#This Row],[Prix de vente ($)]]/Table2[[#This Row],[Superficie totale (ha)]] -> 7107.5124 | AI34: =Bois!$G6/Bois!$AD6 -> #DIV/0!
A35: 26183363 | C35: 44252 | D35: Albert BOURDEAU, Dixie ARBUTHNOT | E35: FLORIAN ROBERT & FILS INC | F35: 5944131 | G35: 700000 | I35: Papineau | J35: Ripon | K35: Chemin Viceroy, Ripon | L35: 45.844299 | M35: -75.106484 | N35: 82.84 | O35: non | P35: déclivité | Q35: 77.84 | R35: 0 | S35: Feuillus | T35: 0.6 | U35: 0.4 | AC35: 22.5 | AF35: presence de batiments, tres accesible | AH35: =Table2[[#This Row],[Prix de vente ($)]]/Table2[[#This Row],[Superficie totale (ha)]] -> 8450.0241
A36: 26115144 | C36: 44260 | D36: DÉBOISEMENT G.C.G. INC (Carl BOULET) | E36: Mathieu BERNIÈRE, Isabelle CHABOT | F36: 6 417 583 | G36: 34500 | I36: Dorchester | J36: Saint-Luc-de- Bellechasse | K36: 12e Rang Saint-Luc-de- Bellechasse | L36: 46.523723 | M36: -70.470488, | N36: 1.64 | O36: non | P36: Plane | Q36: 1.64 | S36: Feuillus | T36: 0.9 | U36: 0.1 | AF36: Densité couvert 90-100% | AH36: =Table2[[#This Row],[Prix de vente ($)]]/Table2[[#This Row],[Superficie totale (ha)]] -> 21036.585 | AI36: =Bois!$G7/Bois!$AD7 -> #DIV/0!
A37: 26171908 | C37: 44284 | D37: 9155-5904 QUÉBEC INC | E37: GESTION FRANCOIS ROUSSIN INC | F37: 3 813 929, 3 815 781 | G37: 335000 | I37: La côte-de-Beaupré | J37: Sainte-Anne-de-Beaupré | K37: Avenue-Royale, Sainte-Anne-de-Beaupré | L37: 47.018347 | M37: -70.961798 | N37: 46.21 | O37: oui | P37: déclivité | Q37: 40.93 | R37: 2.4 | S37: Feuillus | T37: 0.9 | U37: 0.1 | AC37: 19.5 | AH37: =Table2[[#This Row],[Prix de vente ($)]]/Table2[[#This Row],[Superficie totale (ha)]] -> 7249.5131
A38: 26199842 | C38: 44295 | D38: Roland RACINE | E38: J-M Leclerc Excavation inc | F38: 6 212 177, 6 212 148 | G38: 150000 | I38: La côte-de-Beaupré | J38: Saint-Tite-des-Caps | K38: Route 138, Saint-Tite-des-Caps | L38: 47.116667 | M38: -70.809745 | N38: =16.71+13.99 -> 30.7 | O38: non | P38: legère déclivité | Q38: =30.7-4.1 -> 26.6 | R38: 0 | S38: Feuillus | T38: 0.7 | U38: 0.3 | AC38: 5.7 | AF38: accesible | AH38: =Table2[[#This Row],[Prix de vente ($)]]/Table2[[#This Row],[Superficie totale (ha)]] -> 4885.9935
A39: 26206431 | C39: 44298 | D39: François ROBERGE | E39: Ghislain SÉVIGNY, Danielle LAVOIE | F39: 4735650 | G39: 40000 | I39: Jacques-Cartier | J39: Stoneham-et-Tewkesbury | K39: chemin du Bruant Stoneham-et-Tewkesbury | L39: 46.941059 | M39: -71.364145 | N39: 8.25 | O39: non | P39: pente | Q39: 8.25 | S39: F | T39: 0.8 | U39: 0.2 | V39: 70-79% | AC39: 3.5 | AF39: Enclavé. | AH39: =Table2[[#This Row],[Prix de vente ($)]]/Table2[[#This Row],[Superficie totale (ha)]] -> 4848.4848 | AI39: #DIV/0!
A40: 26221712 | C40: 44302 | D40: LES ENTREPRISES FORESTIÈRES LEBLANC INC | E40: Gabriel LEVESQUE-NADEAU, Lory PLANTE-MICHELIN | F40: 6411246 | G40: 40000 | I40: Dorchester | J40: Saint-Luc-de- Bellechasse | K40: route Laflamme, Saint-Luc-de-Bellechasse | L40: 46.544574 | M40: -70.556879 | N40: 3.49 | O40: non | P40: Plane | Q40: 3.49 | S40: Mixte (dominance feuillus) | T40: 0.7 | U40: 0.3 | AF40: Densité couvert 80-89% | AH40: =Table2[[#This Row],[Prix de vente ($)]]/Table2[[#This Row],[Superficie totale (ha)]] -> 11461.318 | AI40: =Bois!$G8/Bois!$AD8 -> #DIV/0!
...

Sheet Terre
A1: No d'enr. | B1: SIA | C1: Date de l'acte ou de l'avant contrat | D1: Vendeur | E1: Acheteur | F1: Lots | G1: Prixdevente($) | H1: Prix de vente redressé au temps ($) | I1: MRC | J1: Ville/Municipalité | K1: Adresse complète | L1: Latitude | M1: Longitude | N1: Superficie totale (ha) | O1: Zone agricole (CPTAQ) | P1: Topographie | Q1: Classe de sol dominante | R1: Sous-classe dominante | S1: Superficie cultivée (ha) | T1: Source superficie cultivée | U1: Superficie drainée (ha) | V1: Source superficie drainée | W1: Type de sol | X1: Type de culture | Y1: Superficie boisée (ha) | Z1: Superficie plantation | AA1: Superficie terrain résidentiel (m²) | AB1: Droit acquis | AC1: Maison(s) | AD1: Valeur contributive maison(s) + terrain ($) | AE1: Source valeur constributive maison(s) + terrain ($) | AF1: Bâtiments agricoles | AG1: Valeur contributive bâtiments agricoles ($) | AH1: Source valeur constributive bâtiments agricoles | AI1: Autres inclusions | AJ1: Valeur autres inclusions ($) | AK1: Observations | AL1: Décisions CPTAQ | AM1: Taux unitaire global ($/ha)
A2: 22309676 | C2: 42507 | D2: Réjean Lemire, Claude Lemire | E2: Michel Proulx | F2: 5433069 | G2: 36000 | I2: Nicolet-Yamaska | J2: Baie-du-Febvre | K2: Route Marie-Victorin Baie-du-Febvre | L2: 46.154336 | M2: -72.706115 | N2: 6.25 | O2: Oui | P2: Plane | Q2: 4 | R2: FW | S2: =4.7+0.8 -> 5.5 | T2: FADQ | AK2: Potentiel acéricole dans les terrains riverrains,(érables rouges) | AM2: =G2/N2 -> 5760
A3: 22859457 | C3: 42696 | D3: Ovide Savard | E3: La Ferme des Quatre-Temps Inc (Marguerite Tremblay) | F3: 5401041 | G3: 323000 | I3: Charlevoix-Est | J3: La Malbaie | K3: Boulevard Malcolm-Fraser La Malbaie | L3: 47.797659 | M3: -69.934839 | N3: =524558.875/10000 -> 52.455888 | O3: oui | P3: Légère pente | Q3: 3 | R3: P | S3: =1+0.7+1.8+3.2+1.8+0.8+3.4 -> 12.7 | T3: FADQ | Y3: =Terre!$N34-Terre!$S34 -> 10.27 | AK3: bande de terre située entre deux terres qui étais probablement manquante pour la compagnie, non drainée | AM3: =G3/N3 -> 6157.5548
A4: 23128070 | C4: 42791 | D4: FERME MARTEL 1999 INC (Jean-Jacques MARTEL) | E4: LES BELLES RÉCOLTES DE CHARLEVOIX INC (Stéphane DUFOUR) | F4: 5 400 604, 3 560 775, 5 063 796, 5 400 619 | G4: 430000 | I4: Charlevoix-Est | J4: La Malbaie | K4: chemin des Loisirs et chemin de la Vallée La Malbaie | L4: 47.688972 | M4: -70.171369 | N4: 70.1 | O4: oui | P4: Légère pente | Q4: 3 | R4: FMT | S4: =48.4+9 -> 57.4 | T4: FADQ | Y4: =6.4+0.2 -> 6.6 | AK4: Vente de 2 terres, en face de la rivière, non drainées,voisin d'une propriété acéricole | AM4: =G4/N4 -> 6134.0942
A5: 24059816 | B5: 12936685 | C5: 43273 | D5: Camille TREMBLAY | E5: Denis LAPOINTE | F5: 5439978 | G5: 60000 | I5: Charlevoix-Est | J5: Saint-Irénée | K5: chemin des Bains Saint-Irénée | L5: 47.533781 | M5: -70.225115 | N5: =1391568.5/10.7639/10000 -> 12.928107 | O5: oui | P5: Relativement plane | Q5: 5 | R5: PT | S5: =Terre!$N62-Terre!$Y62 -> 94.1 | T5: Mesures Demeter | Y5: 3.1 | AK5: vente à un prix élevé à la municipalité | AM5: =G5/N5 -> 4641.0507
A6: 24386780 | C6: 43490 | D6: La BLEUETIÈRE BEAULIEU INC. | E6: 9161-2754 QUÉBEC INC. | F6: 5 219 647 | G6: 100000 | I6: Manicouagan | J6: pointe-lebel | K6: Route de l'aréoport, Pointe-Lebel | L6: 49.140934 | M6: -68.205762 | N6: 15 | O6: oui | P6: plane | Q6: 4 | R6: FD | S6: 11.4 | T6: FADQ | U6: 0 | V6: infosol | Y6: 0 | AK6: très grand terrains boisée combiné avec terre agricole. FADQ médiocre sur terre donc certaine mesures sont faites a la main. | AM6: =G6/N6 -> 6666.6667
A7: 24495986 | C7: 43552 | D7: ANDRÉ LEMAIRE INC | E7: CULTURES ROUSSEAU INC (Paul ROUSSEAU) | F7: 5743147, 5745024, 5 743 148, 5433045, 5434246, 5434247, 5434264, 5 433 041 | G7: 1992000 | I7: Nicolet-Yamaska | J7: Baie-du-Febvre | K7: Rg du Petit-Bois Baie-du-Febvre | L7: 46.112650 | M7: -72.773585 | N7: =(137446.3+168074.1+2208+183126+24253.2+137398.2+60183.3+10222.5)/10000 -> 72.29116 | O7: oui | P7: Plane | Q7: 3 | R7: FW | S7: =6.7+17+45.5+13.3-12.1 -> 70.4 | T7: FADQ | U7: =16.81+18.31+13.74 -> 48.86 | AK7: non drainée | AM7: =G7/N7 -> 27555.236
A8: 24718742 | C8: 43643 | D8: Mario GAMELIN | E8: Marie-Philippe FRENETTE DANEAU | F8: 5744548 | G8: 50000 | I8: Nicolet-Yamaska | J8: Pierreville | K8: chemin du Marais-Blazon Pierreville | L8: 46.109543 | M8: -72.900294 | N8: 6.06 | O8: oui | P8: Plane | Q8: 3 | R8: FW | S8: 5.5 | T8: FADQ | AK8: Non drainé, zone agricole mais non délimité par la FADQ | AM8: =G8/N8 -> 8250.8251
A9: 25326259 | C9: 43724 | D9: FERME PROMAS INC (Martine Massé) | E9: FERME MICHDALE (Michael Leduc) | F9: 5 691 498, 5 691 427, 5 691 439 | G9: 621500 | I9: Les Appalaches | J9: Saint-Julien | K9: 2e Rang Ouest Saint-Julien | L9: 46.046685 | M9: -71.567924 | N9: =10.59+12.89+55.29 -> 78.77 | O9: Oui | P9: Plane | Q9: 7 | R9: PT | S9: =10.59+9.49+24.99 -> 45.07 | T9: Mesures Demeter | U9: 0 | X9: Prairie | Y9: =3.4+30.3 -> 33.7 | AF9: 3 hangars, fosse | AG9: =102700+36000 -> 138700 | AH9: Acte | AI9: Équipements, matériel | AJ9: =60800+22000 -> 82800 | AK9: En partie mineure de classe 5, droit d'usage conféré au vendeur (superficie négligeable) | AM9: =G9/N9 -> 7890.0597
A10: 25161637 | C10: 43846 | D10: Pavage C.S.F. Inc. | E10: 9122-3388 Quebec Inc. | F10: 5456717 | G10: 653 175 | J10: Notre-Dame-De-L'Ile-Perrot | K10: 0 | AJ10: Petite bois, non CPTAQ | AM10: =G10/N10 -> #VALUE!
A11: 25160283 | C11: 43850 | D11: 2858967 CANADA INC Claude DESROCHERS | E11: 9391-5619 QUÉBEC INC Pierre COUILLARD | F11: 6 312 083, 5 310 276 | G11: 1500000 | J11: Saint-Marc-sur-Richelieu | K11: Rue Richelieu, Saint-Marc-sur-Richelieu | N11: =0.24+36.65 -> 36.89 | O11: Oui | P11: plane | Q11: 4 | R11: FW | S11: =10.7+18.8 -> 29.5 | U11: =Table3[[#This Row],[Superficie cultivée (ha)]] -> 29.5 | Y11: 5 | AF11: 1 hangar (mauvais état) | AM11: =G11/N11 -> 40661.426
A12: 25184870 | C12: 43859 | D12: Sylvain TESSIER | E12: Hughes LEBOEUF | F12: 4 175 797, 4 176 629 | G12: 150000 | I12: Les Chenaux | J12: Sainte-Anne de la Pérade | K12: Sainte-Anne de la Pérade | L12: 46.626915 | M12: -72.228613 | N12: =8.39+8.46 -> 16.85 | O12: oui | P12: Plane | Q12: 3 | R12: W | S12: =4.6+6.2 -> 10.8 | T12: FADQ | Y12: 5.7 | AK12: non drainé | AM12: =G12/N12 -> 8902.0772
A13: 25184865 | C13: 43859 | D13: FERME BOIS-DU-MERLE S.E.N.C. (Marcel et Martin Juneau) | E13: FERME RAINIER ET ASSOCIÉS S.E.N.C (Christian et Mario Germain) | F13: 4175461 | G13: 500000 | I13: Les Chenaux | J13: Sainte-Anne de la Pérade | K13: Sainte-Anne de la Pérade | L13: 46.564578 | M13: -72.241371 | N13: 27.69 | O13: oui | P13: Plane | Q13: 3 | R13: W | S13: =9.1+7.2+9.9 -> 26.2 | T13: FADQ | AK13: enclavé, servitude de passage | AM13: =G13/N13 -> 18057.06
A14: 25205856 | C14: 43873 | D14: Jocelyn GIROUARD | E14: FERME GHISLAIN CLOUTIER INC Ghislain CLOUTIER | F14: 2706581 | G14: 400000 | I14: Les Maskoutains | J14: St-Barnabé-Sud | K14: Rang St-Amable, St-Barnabé-Sud | L14: 45.759554 | M14: -72.904675 | N14: 7.69 | O14: Oui | P14: plane | Q14: 2 | R14: W | S14: 7.3 | AM14: =G14/N14 -> 52015.605
A15: 25225318 | C15: 43882 | D15: FERME P. & M. CHAMPAGNE INC | E15: FERME TERREBONNE INC | F15: 2 849 451, 2 849 450, 3 283 310 | G15: 309500 | I15: Lévis | J15: Lévis | K15: chemin petit St Jean, Lévis | L15: 46.671480 | M15: -71.318910 | N15: 39.33 | O15: oui | P15: Plane | Q15: 4 | R15: WP | S15: 23.6 | T15: FADQ | Y15: 13.4 | AK15: non drainé | AM15: =G15/N15 -> 7869.311
A16: 25270667 | C16: 43907 | D16: LE SANCTUAIRE DE LA VALLÉE DU RICHELIEU INC. André SIMONEAU | E16: 9342-4497 QUÉBEC INC Dave VILLENEUVE | F16: 5132029 | G16: 750000 | I16: La-Vallée-du-Richelieu | J16: St-Mathieu-de-Beloeil | K16: Rue Bernard-PilonSt-Mathieu-de-Beloeil | L16: 45.581457 | M16: -73.277008 | N16: 2.82 | O16: Oui | P16: plane | Q16: 2 | R16: W | S16: 2.6 | AK16: Solde du prix de 550 000 $ au plus tard soit au moment du dézonage (agricole) soit au 13 mars 2023 | AL16: 335956 | AM16: =G16/N16 -> 265957.45
A17: 26079068 | C17: 43911 | D17: Claude CHÉNIER | E17: FERME NINON INC | F17: 4 652 183, 6 370 298 | G17: 480000 | I17: Papineau | J17: Lochaber-Partie-Ouest | K17: Rang 4e, Lochaber-Partie-Ouest | L17: 45.591390 | M17: -75.287421 | N17: 57.67 | O17: oui | P17: Legere pente | Q17: 3 | R17: F | S17: 31.9 | T17: FADQ | U17: 0 | V17: infosol | Y17: 24.25 | AK17: non drainé | AM17: =G17/N17 -> 8323.2183
A18: 25344540 | C18: 43950 | D18: FERME DIANE S.E.N.C. Diane PHANEUF et Patrick LAVALLÉE | E18: Lison BÉDARD | F18: 2708676 | G18: 190000 | J18: Saint-Jude | K18: Rang des Quarante-huit, Saint-Jude | L18: 45.808984 | M18: -72.967530 | N18: 13.65 | O18: Oui | P18: plane | Q18: 2 | R18: X | S18: 6.9 | Y18: 4.5 | AM18: =G18/N18 -> 13919.414
A19: 25369557 | C19: 43963 | D19: Jocelyn RICHER | E19: SOCIÉTÉ CBCA SNC Chrétien ARCHAMBAULT | F19: 3698783 | G19: 300000 | J19: Saint-Denis-sur-Richelieu | K19: 3e rang des Moulins est, Saint-Denis-sur-Richelieu | L19: 45.776104 | M19: -73.123560 | N19: 5.13 | O19: Oui | P19: plane | Q19: 2 | R19: W | S19: 4.8 | U19: =Table3[[#This Row],[Superficie cultivée (ha)]] -> 4.8 | AM19: =G19/N19 -> 58479.532
A20: 25396662 | C20: 43976 | D20: Marie-Joseph PIGEON | E20: FERME VIAGRICO INC Bruno VIENS et Jessica BÉRUBÉ | F20: 5 310 296, 5 312 004, 5 312 098 | G20: 1200000 | J20: Saint-Marc-sur-Richelieu | L20: 45.731186 | M20: -73.202806 | N20: =26.12+16.49+0.09 -> 42.7 | O20: Oui | P20: plane | Q20: 2 et 4 | R20: W | S20: =12.8+2.6+6+7.8 -> 29.2 | Y20: 5.5 | AM20: =G20/N20 -> 28103.044
A21: 25451290 | C21: 43994 | D21: Ghyslain PROVOST, JARDINS PROVOST INC | E21: 9417-9082 QUÉBEC INC Serge ARCHAMBAULT | F21: 1 912 197, 1 912 199, 1 912 733, 1 912 952, 1 912 953 | G21: 1175000 | I21: Marguerite-D'Youville | J21: Boucherville | K21: 1381, chemin Général-Vanier à Boucherville | N21: =6.05+6.75+0.43+7.68+2.59 -> 23.5 | Q21: 2 | R21: W | S21: 16.6 | AF21: Kiosque de vente, hangar 90'x50' | AK21: le tracteur John Deer modèle 3320, 2011, dont le numéro d’identification est le 1LV3320HKBH711054; et, - un camion GMC modèle Savana, 2002, dont le numéro d’identification est le 1GTFG25M921240884.un semoir à blé d’inde; - un vibroculteur; - un set de roulettes; et, - un véhicule de Marque Dodge, modèle RMV, année 2002, dont le numéro d’identification est le 2B7JB21YX2K132098 | AM21: =G21/N21 -> 50000
A22: 26427913 | C22: 44003 | D22: FERME HÉLÉNOISE INC | E22: FERME BIENVU & FILS INC. | F22: 1 956 966, 1 959 926 | G22: 3385000 | I22: les Maskoutains | J22: Sainte-Hélène-de-Bagot | K22: 2e rang Sainte-Hélène-de-Bagot | L22: 45.714528 | M22: -72.758705 | N22: 70.91 | O22: OUI | P22: Plane | Q22: 3 | R22: FW | S22: 63.5 | T22: FADQ | U22: 63.5 | V22: infosol | Y22: 3.1 | AA22: 2218.5 | AC22: 1 | AF22: Bâtiment d’élevage, garage, Silos et Fosse à lisier | AK22: Drainé | AM22: =G22/N22 -> 47736.567
A23: 25541105 | C23: 44027 | D23: FERME BAZINET ET FILS INC | E23: Martin BRODEUR-CHOQUETTE | F23: 3407614 | G23: 538594 | I23: La-Vallée-du-Richelieu | J23: Saint-Charles-sur-Richelieu | L23: 45.681639 | M23: -73.171122 | N23: 12.52 | O23: Oui | P23: plane | Q23: 2 | R23: W | S23: 11.6 | U23: =Table3[[#This Row],[Superficie cultivée (ha)]] -> 11.6 | AM23: =G23/N23 -> 43018.69
A24: 25629542 | B24: 22138106 | C24: 44034 | D24: Martin LAPOINTE, Manon BOUCHARD | E24: Pierre PAQUET | F24: 5438957 | G24: 300000 | I24: Charlevoix | J24: Les Éboulements | K24: 2490, Route du Fleuve Les Éboulements | L24: 47.479265 | M24: -70.309319 | N24: =502738.98/10.7639/10000 -> 4.6706025 | O24: oui | P24: Plane | Q24: 3 | R24: P | S24: =Terre!$N38-Terre!#REF! -> #REF! | T24: Mesures Demeter | AF24: Bâtiment de 2006 | AG24: 140000 | AI24: Tracteur et équipements aratoires | AJ24: 30000 | AK24: Presence de bâtiment | AM24: =G24/N24 -> 64231.542
A25: 25713777 | C25: 44057 | D25: Steeve POULIN | E25: FERME FAMILLE ST-HILAIRE S.E.N.C. | F25: 4340477 | G25: 40000 | I25: Robert-Cliche | J25: Saint-Odilon-de-Cranbourne | K25: 8e Rang Ouest Saint-Odilon-de-Cranbourne | L25: 46.305958 | M25: -70.687122 | N25: 5.61 | O25: Oui | P25: Plane | Q25: 5 | R25: PW | S25: 3.8 | T25: Mesures Demeter | V25: infosol | X25: Maïs fourrager | Y25: 1.8 | AK25: Drainée | AM25: =G25/N25 -> 7130.1248
A26: 25 640 643 | C26: 44070 | D26: Pachanos Margaret Rose | E26: Venne Matthieu | F26: 5 372 421, 5 373 988 | G26: 40000 | I26: La Vallé-de-l'Or | J26: Sanneterre | K26: ch Croinor | L26: 48.348934 | M26: -77.26329 | N26: 12.96 | O26: oui/non | P26: Plane | Q26: 4 | R26: TD | S26: 5.4 | T26: Mesures aériennes | W26: Argileux | Y26: 6.9 | AK26: La terre semble plus cultivé, la friche repousse | AM26: =G26/N26 -> 3086.4198
A27: 25662799 | C27: 44078 | F27: 6367545 | G27: 240000 | I27: Témiscouata | J27: Témiscouata-sur-le-Lac | K27: rue Commerciale Nord, Témiscouata-sur-le-Lac | L27: 47.652577 | M27: -68.835944 | N27: 48.89 | O27: oui | P27: Légère pente | Q27: 3 | R27: tp | S27: =8.5+0.6+2.8 -> 11.9 | T27: fadq | Y27: 34 | AM27: =G27/N27 -> 4908.9793
A28: 25700380 | C28: 44096 | D28: Yvon DAUPHINAIS | E28: 9320-3792 Québec Inc Mohamed-Elyès JOUINI | F28: 2 600 783, 2 601 574 | G28: 410000 | I28: La-Vallée-du-Richelieu | J28: Carignan | K28: Chemin Bellerive, Carignan | L28: 45.421964 | M28: -73.367582 | N28: =20.25+12.54 -> 32.79 | O28: Oui | P28: plane | Q28: 2 | R28: W | S28: =5.8+0.08+3.9+0.7+1.5 -> 11.98 | Y28: 13.2 | AK28: à l’intérieur d’une zone d’inondation de grand courant (récurrence 0-20 ans) et faible courant (récurrence 20-100 ans) | AM28: =G28/N28 -> 12503.812
A29: 25934008 | C29: 44106 | D29: LES GRAINS DE LA MAURICIE INC (Roger GAUTHIER, Jacqueline HÉBERT) | E29: Vincent COULOMBE | F29: 4 175 743, 4 175 753, 4 306 126, 5 618 790, 5 618 345, 5 618 903, 5 619 121 | G29: 1070000 | I29: Les Chenaux | J29: Saint-Prosper-de-Champlain | K29: Rang Sainte- Elisabeth Saint-Prosper-de-Champlain | L29: 46.621800 | M29: -72.249023 | N29: =7.74+13.97+1.57+5.89+14.82+4.57+23.17 -> 71.73 | O29: oui | P29: Plane | Q29: 2 | R29: W | S29: =7.74+12.9+0.8+3.6+12.6+4.3+5.7+7.3 -> 54.94 | T29: FADQ | Y29: =0.8+0.8+1+9.5 -> 12.1 | AM29: =G29/N29 -> 14917.05
A30: 27123066 | C30: 44116 | D30: Laval RICHARD, Margaret POULIN | E30: FERME PIAL INC (Mathieu CHÉNARD) | F30: 6 422 974, 5 170 539 | G30: 200000 | I30: Kamouraska | J30: Saint-Josephde- Kamouraska | K30: 4e Rang Est St-Joseph-de-Kamouraska | L30: 47.627697 | M30: -69.640950 | N30: =(186034.297+110432.203)/10000 -> 29.64665 | O30: oui | P30: Relativement plane | Q30: 4 | R30: FM | S30: =0.2+8.5+3.5+2.6+1.8 -> 16.6 | T30: FADQ | Y30: =Terre!$N66-Terre!$S66 -> 0.98 | AM30: =G30/N30 -> 6746.1248
A31: 25764750 | C31: 44119 | D31: André LAMBERT | E31: FERME BÉLANGEOISE INC | F31: 1 964 910, 3 387 636 | G31: 100000 | I31: Lévis | J31: Lévis | K31: chemin Filteau, Lévis | L31: 46.646697 | M31: -71.441468 | N31: 12.71 | O31: oui | P31: Plane | Q31: 4 | R31: WP | S31: 7.2 | T31: FADQ | Y31: 3.3 | AL31: 441527 (usage résidentiel, exclus de la vente) | AM31: =G31/N31 -> 7867.8206
A32: 25767842 | C32: 44120 | D32: Serge MACHABEE, Marcel CHARTRAND, Isabelle CHARTRAND, Patrice CHARTRAND | E32: SAFRAN AGRICULTURE S.E.N.C. Sasan BAYAT MAKOU, Fereidoun HARANDIAN, Nader SADEGHI et Ramin KHODAYARI | F32: 6185182 | G32: 1800000 | J32: Longueuil | K32: Grande Alle, Longueuil | L32: 45.445508 | M32: -73.397179 | N32: 52.83 | O32: Oui | P32: plane | Q32: 2 | R32: W | S32: =2.3+2.1+2.9+3.8+6.4+2.9+6.6+2.4+3.4 -> 32.8 | Y32: 15 | AM32: =G32/N32 -> 34071.55
A33: 26442237 | C33: 44123 | D33: Alain BERNIER | E33: FERME ELAMARC INC. | F33: 2 819 306, 6 434 818, 6 434 819 | G33: 525000 | I33: Bellechasse | J33: Saint-Charles-de- Bellechasse | K33: rang Sud-Ouest | L33: 46.728979 | M33: -70.951184 | N33: 29.93 | O33: Oui | P33: Plane | Q33: 3 | R33: W | S33: 21.2 | T33: Déméter et FADQ | U33: Oui | V33: Infosols | X33: Orge, foin | AK33: Valeur inclusions selon acte | AM33: =G33/N33 -> 17540.929
A34: 25847015 | C34: 44148 | D34: Hélène BERGERON | E34: Samuel BEAURIVAGE | F34: 2 245 214, 2 332 167, 5 663 807 | G34: 262500 | I34: Lévis | J34: Lévis | K34: route Marie-Victorin, Lévis | L34: 46.680184 | M34: -71.483376 | N34: 20.27 | O34: oui | P34: Plane | Q34: 3 | R34: W | S34: 10 | T34: FADQ et mesures Démeter | Y34: 6.5 | AM34: =G34/N34 -> 12950.173
A35: 26058624 | C35: 44166 | D35: Bibianne Daneau | E35: Denis Courchesne | F35: 5 743 071, 5 743 223 | G35: 1043700 | I35: Nicolet-Yamaska | J35: Pierreville | K35: Rg Courchesne, Rg du Petit-Bois Pierreville | L35: 46.107132 | M35: -72.813624 | N35: =25.8+21.49 -> 47.29 | O35: oui | P35: Plane | Q35: 3 et 4 | R35: FW | S35: =9.3+3.9+24.4-0.3 -> 37.3 | T35: Demeter | U35: 25.8 | V35: infosols | Y35: 0.4 | AM35: =G35/N35 -> 22070.205
A36: 25988798 | C36: 44210 | D36: 9377-2416 Quebec Inc. | E36: Teri Chelminski | F36: 3977389 | G36: 607 959 | J36: 0 ch de Senneville | K36: 0 | AJ36: Boisé pour constrution | AM36: =G36/N36 -> #VALUE!
A37: 26028123 | C37: 44211 | D37: FERME DATONY ENR | E37: FERME L. POULIOT & FILS INC., | F37: 3 586 505, 3 586 507 | G37: 615000 | I37: Bellechasse | J37: Honfleur | K37: Rang Buckland | L37: 46.619615 | M37: -70.82386 | N37: 41.6 | O37: Oui | P37: Legere pente | Q37: 7 | R37: P | S37: =15.4+8.7+16.1 -> 40.2 | T37: FADQ | U37: 0 | V37: infosols | X37: Foin, céréales | AM37: =G37/N37 -> 14783.654
A38: 26038743 | C38: 44230 | D38: Anne LEGAULT | E38: 9423-0695 QUÉBEC INC | F38: 4 852 645, 6 302 527, 4 852 680 | G38: 280000 | I38: Papineau | J38: Lochaber | K38: Route 148 Est, Lochaber | L38: 45.600339 | M38: -75.215190 | N38: 42.62 | O38: oui | P38: Legere pente | Q38: 2 | R38: W | S38: 24.7 | T38: FADQ | U38: 24.7 | V38: infosol | Y38: 15.8 | AM38: =G38/N38 -> 6569.6856
A39: 26366489 | C39: 44238 | D39: Cyrille LEFEBVRE | E39: FERME GERVILLE INC (Simon Lefebvre) | F39: 5 433 072, 5 434 197 | G39: 1200000 | I39: Nicolet-Yamaska | J39: Baie-du-Febvre | K39: Route Marie-Victorin Baie-du-Febvre | N39: 60.83 | O39: oui | P39: Plane | Q39: 2 | R39: W | S39: =3.9+3.7+1.5+1.7+2.7+0.8+20.7+10.6 -> 45.6 | T39: FADQ | U39: =2.7+0.8+20.7+10.6 -> 34.8 | V39: infosols | Y39: 11.5 | AL39: 435204 | AM39: =G39/N39 -> 19727.108
A40: 26855053 | C40: 44248 | D40: LORRAIN HEPPELL | E40: Nadine HEPPELL | F40: 5 148 902, 5 148 914, 5 149 044 | G40: 270000 | I40: Manicouagan | J40: Ragueneau | K40: 2ieme rang, Ragueneau | L40: 49.099037 | M40: -68.46945 | N40: 143.99 | O40: oui | P40: legere pente | Q40: 7 | R40: w | S40: 35.4 | T40: FADQ et mesures Démeter | U40: 0 | V40: infosol | Y40: 105.59 | AA40: 3 | AM40: =G40/N40 -> 1875.1302
...

Sheet Feuil1
A1: Région administrative | B1: Mauricie
A3: MRC | B3: Ville/Municipalité
A4: Les Chenaux | B4: Batiscan
B5: Sainte-Anne de la Pérade
B6: Sainte-Geneviève de Batiscan
B7: Saint-Prosper-de-Champlain
A8: Total Les Chenaux
A9: Total général

Sheet Registre des recherches
A1: Nom de l'analyste | B1: Type de recherche | C1: Date début | D1: Date fin | E1: MRC | F1: Municipalité | G1: Mot clé ferme uniquement | J1: Type de recherche | K1: MRC
A2: Simon | B2: Terres | C2: 45413 | D2: 45580 | E2: Portneuf | G2: oui | J2: Terres et bois | L2: Ferme
A3: Kaka | B3: Terres et bois | C3: 44197 | D3: 45581 | E3: La Côte-de-Beaupré | G3: oui | J3: Terres | K3: Abitibi | L3: Érablière | M3: oui
A4: Kaka | B4: Terres et bois | C4: 45292 | D4: 45593 | E4: Lotbinière | J4: Bois | K4: Abitibi-Ouest | L4: FPE | M4: non
A5: Kaka | B5: Terres et bois | C5: 44927 | D5: 45291 | E5: Lotbinière | F5: Saint-Gilles | J5: Terres -5ha | K5: Acton
A6: Simon | B6: Terres | C6: 44927 | D6: 45600 | F6: Sainte-Martine | G6: oui | J6: Bois -5ha | K6: Antoine-Labelle
A7: Eloi | B7: Terres et bois | C7: 44197 | D7: 45601 | E7: Manicouagan | F7: Ragueneau | J7: Autre (préciser) | K7: Argenteuil
A8: Eloi | B8: Terres et bois | C8: 43466 | D8: 44561 | E8: Manicouagan | J8: Acéricole | K8: Arthabaska
A9: Eloi | B9: Terres et bois | C9: 44927 | D9: 45609 | F9: Saint-Lambert-de-Lauzon | K9: Avignon
A10: Eloi | B10: Terres et bois | C10: 45292 | D10: 45610 | E10: La Nouvelle-Beauce | K10: Beauce-Centre
A11: Eloi | B11: Bois | C11: 44197 | D11: 45621 | F11: Lac frontière | K11: Beauce-Sartigan
A12: Eloi | B12: Bois | C12: 44927 | D12: 45621 | F12: Sainte-Lucie-de-Beauregard | K12: Beauharnois-Salaberry
A13: Eloi | B13: Terres et bois | C13: 44562 | D13: 45623 | E13: Lotbinière | F13: Saint-Agapit | K13: Bécancour
A14: Eloi | B14: Terres et bois | C14: 44562 | D14: 45623 | E14: Lotbinière | F14: Saint-Gilles | K14: Bellechasse
A15: Eloi | B15: Terres et bois | C15: 45292 | D15: 45631 | E15: La Mitis | K15: Bonaventure
A16: Eloi | B16: Terres et bois | C16: 44927 | D16: 45637 | E16: L'Érable | F16: Lyster | K16: Brome-Missisquoi
A17: Eloi | B17: Terres et bois | C17: 44927 | D17: 45637 | F17: Saint-Sylvestre | K17: Charlevoix
A18: Eloi | B18: Terres et bois | C18: 44927 | D18: 45649 | F18: Berthier-sur-mer | K18: Charlevoix-Est
A19: Eloi | B19: Terres et bois | C19: 44927 | D19: 45649 | F19: Saint-francois-de-la-rivère-du-sud | K19: Coaticook
A20: Eloi | B20: Terres | C20: 44927 | D20: 45292 | E20: La Mitis | K20: D'Autray
A21: Eloi | B21: Terres | C21: 45292 | D21: 45680 | E21: Acton | K21: Deux-Montagnes
A22: kaka | B22: Terres | C22: 44562 | D22: 45663 | E22: Beauce-Sartigan | G22: oui | K22: Drummond
E23: Les Etchemins | G23: oui | K23: Joliette
E24: Robert-Cliche | G24: oui | K24: Kamouraska
A25: kaka | B25: Terres et bois | C25: 45474 | D25: 45700 | E25: Kamouraska | G25: oui | K25: La Côte-de-Beaupré
A26: Eloi | B26: Bois | C26: 45566 | D26: 45727 | E26: Portneuf | K26: La Côte-de-Gaspé
A27: Simon | B27: Terres | C27: 45597 | D27: 45765 | F27: Lévis | K27: Lac-Saint-Jean-Est
A28: Simon | B28: Terres | C28: 45597 | D28: 45765 | F28: Beaumont | K28: La Haute-Côte-Nord
A29: Simon | B29: Terres | C29: 45597 | D29: 45765 | F29: St-Charles-de-Bellechasse | K29: La Haute-Gaspésie
A30: Simon | B30: Terres | C30: 45597 | D30: 45765 | F30: St-Henri | K30: La Haute-Yamaska
A31: Simon | B31: Terres | C31: 45663 | D31: 45769 | E31: Beauce-Sartigan | K31: La Jacques-Cartier
A32: Simon | B32: Acéricole | C32: 45663 | D32: 45769 | E32: Beauce-Sartigan | K32: La Matanie (ou Matane [DR])
A33: Simon | B33: Terres | C33: 45108 | D33: 45773 | E33: Québec | K33: La Matapédia
A34: Simon | B34: Bois | C34: 45108 | D34: 45773 | E34: Québec | K34: La Mitis
A35: Simon | B35: Terres | C35: 45703 | D35: 45773 | E35: Portneuf | K35: La Nouvelle-Beauce
A36: ELoi | B36: Bois | C36: 45292 | D36: 45620 | E36: L'Islet | K36: La Rivière-du-Nord
A37: Eloi | B37: Terres et bois | C37: 45444 | D37: 45782 | E37: Vaudreuil-Soulanges | K37: L'Assomption
A38: Eloi | B38: Terres et bois | C38: 45444 | D38: 45782 | E38: Deux-Montagnes | K38: La Vallée-de-la-Gatineau
A39: ELOI | B39: Terres et bois | C39: 45292 | D39: 45784 | E39: Lotbinière | F39: Sainte-croix,Saint-antoine-de-tilly,Saint-appolinnaire,Notre-dame-du-sacré-cœur,lotbinière,saintédouard-de-lotbinière | K39: La Vallée-de-l'Or
A40: Eloi | B40: Terres et bois | C40: 45610 | D40: 45792 | E40: Lotbinière | F40: Saint-gilles | K40: La Vallée-du-Richelieu
...
